<robot name="duoArm">

  <link name="lta-body">
    <visual>
      </visual>
    <collision>
      </collision>
    <inertial>
      <origin xyz="0 0 0" rpy="0 0 0"/>
      <mass value="1.0" />  <inertia ixx="0.0" ixy="0"  ixz="0" iyy="0" iyz="0" izz="0" />  </inertial>
  </link>

  <link name="activearm">
    <visual>
      </visual>
    <collision>
      </collision>
    <inertial>
      <origin xyz="0 0 0" rpy="0 0 0"/>
      <mass value="1.0" />  <inertia ixx="0.0" ixy="0"  ixz="0" iyy="0" iyz="0" izz="0" />  </inertial>
  </link>

  <link name="lta-passivarm_2">
    <visual>
      </visual>
    <collision>
      </collision>
    <inertial>
      <origin xyz="0 0 0" rpy="0 0 0"/>
      <mass value="4.0" />  <inertia ixx="0.0" ixy="0"  ixz="0" iyy="0" iyz="0" izz="0" />  </inertial>
  </link>

  <joint name="elbowH" type="revolute">
    <origin xyz="2.720046410331633524e-15 0.12100000000000182832 -0.030000000000000082157" rpy="-5.1648064932760115286e-24 -1.4008023803742507427e-23 2.311678298551733679" />
    <parent link="activearm_2" />
    <child link="lta-passivarm_2" />
    <axis xyz="0 0 1"/>
    <limit effort="1" velocity="20" />
    <joint_properties friction="0.0"/>
  </joint>

  <joint name="motorH" type="revolute">
    <origin xyz="-0.40567438532566235665 -0.33786915395602329371 -0.30166768304039565107" rpy="-1.570796326794896558 -1.4701964741888278176 2.4104629166993733823e-23" />
    <parent link="lta-body" />
    <child link="activearm_2" />
    <axis xyz="0 0 1"/>
    <limit effort="1" velocity="20" lower="-2.0943951023931952626" upper="0"/>
    <joint_properties friction="0.0"/>
  </joint>


</robot>
