<robot xmlns:xacro="http://www.ros.org/wiki/xacro" name="robot">

<link name="world"/>
<joint name="fixed_to_world" type="fixed">
  <parent link="world"/>
  <child link="lta-body"/>
  <origin xyz="0 0 0" rpy="0 0 0"/>
</joint>

<link name="lta-body">
<visual>
<origin xyz="-0.48567411093248913367 -0.35786915395602325596 -0.30187721306692449907" rpy="-1.4279489033863025854e-18 -0.0026191283260932648851 5.4520067672715764569e-16" />
<geometry>
<mesh filename="package://arm/meshes/lta-body.stl"/>
</geometry>
<material name="lta-body_material">
<color rgba="0.79215686274509800047 0.81960784313725487671 0.93333333333333334814 1.0"/>
</material>
</visual>
<collision>
<origin xyz="-0.48567411093248913367 -0.35786915395602325596 -0.30187721306692449907" rpy="-1.4279489033863025854e-18 -0.0026191283260932648851 5.4520067672715764569e-16" />
<geometry>
<mesh filename="package://arm/meshes/lta-body.stl"/>
</geometry>
</collision>
<inertial>
<origin xyz="0 0 0" rpy="0 0 0"/>
<mass value="0" />
  <inertia ixx="0" ixy="0" ixz="0" iyy="0" iyz="0" izz="0" />
  </inertial>
</link>

<link name="activearm">
<visual>
<origin xyz="0 0.060499999999999887201 -0.015000000000000013323" rpy="1.570796326794896558 -1.469367938527859385e-39 0" />
<geometry>
<mesh filename="package://arm/meshes/activearm.stl"/>
</geometry>
<material name="activearm_material">
<color rgba="0.79215686274509800047 0.81960784313725487671 0.93333333333333334814 1.0"/>
</material>
</visual>
<collision>
<origin xyz="0 0.060499999999999887201 -0.015000000000000013323" rpy="1.570796326794896558 -1.469367938527859385e-39 0" />
<geometry>
<mesh filename="package://arm/meshes/activearm.stl"/>
</geometry>
</collision>
<inertial>
<origin xyz="0 0 0" rpy="0 0 0"/>
<mass value="4" />
  <inertia ixx="0.00417" ixy="0" ixz="0" iyy="0.03083" iyz="0" izz="0.03333" />
  </inertial>
</link>

<link name="lta-passivarm">
<visual>
<origin xyz="0 -0.1500000000000000222 0.015000000000000068834" rpy="-1.57079632679489678 -0 0" />
<geometry>
<mesh filename="package://arm/meshes/lta-passivarm.stl"/>
</geometry>
<material name="lta-passivarm_material">
<color rgba="0.79215686274509800047 0.81960784313725487671 0.93333333333333334814 1.0"/>
</material>
</visual>
<collision>
<origin xyz="0 -0.1500000000000000222 0.015000000000000068834" rpy="-1.57079632679489678 -0 0" />
<geometry>
<mesh filename="package://arm/meshes/lta-passivarm.stl"/>
</geometry>
</collision>
<inertial>
<origin xyz="0 0 0" rpy="0 0 0"/>
<mass value="4" />
  <inertia ixx="0.00417" ixy="0" ixz="0" iyy="0.03083" iyz="0" izz="0.03333" />
  </inertial>
</link>

<link name="lta-tooladaptertest">
<visual>
<origin xyz="0.017500000000000182077 -0.036000000000000587086 -0.015000000000000013323" rpy="-1.570796326794896558 -8.2729476294241598222e-24 2.2117724318703883697e-17" />
<geometry>
<mesh filename="package://arm/meshes/tooltest.stl"/>
</geometry>
<material name="tooltest_material">
<color rgba="0.79215686274509800047 0.81960784313725487671 0.93333333333333334814 1.0"/>
</material>
</visual>
<collision>
<origin xyz="0.017500000000000182077 -0.036000000000000587086 -0.015000000000000013323" rpy="-1.570796326794896558 -8.2729476294241598222e-24 2.2117724318703883697e-17" />
<geometry>
<mesh filename="package://arm/meshes/tooltest.stl"/>
</geometry>
</collision>
<visual>
<origin xyz="0.017499999999999960032 0 -0.015000000000000013323" rpy="-1.570796326794896558 -3.6981992672349822831e-33 8.6736173798840354721e-19" />
<geometry>
<mesh filename="package://arm/meshes/lta-tooladaptertest.stl"/>
</geometry>
<material name="lta-tooladaptertest_material">
<color rgba="0.79215686274509800047 0.81960784313725487671 0.93333333333333334814 1.0"/>
</material>
</visual>
<collision>
<origin xyz="0.017499999999999960032 0 -0.015000000000000013323" rpy="-1.570796326794896558 -3.6981992672349822831e-33 8.6736173798840354721e-19" />
<geometry>
<mesh filename="package://arm/meshes/lta-tooladaptertest.stl"/>
</geometry>
</collision>
<inertial>
<origin xyz="0 0 0" rpy="0 0 0"/>
<mass value="4" />
  <inertia ixx="0.00417" ixy="0" ixz="0" iyy="0.03083" iyz="0" izz="0.03333" /></inertial>
</link>

<joint name="toolV" type="revolute">
<origin xyz="5.5511151231257827021e-16 -0.29999999999999860112 0.030000000000000026645" rpy="2.1684325363857330456e-19 -4.201473029868849641e-17 -0.43319888155606767199" />
<parent link="lta-passivarm" />
<child link="lta-tooladaptertest" />
<axis xyz="0 0 1"/>
<limit effort="1" velocity="20" />
<joint_properties friction="0.0"/>
</joint>

<joint name="elbowV" type="revolute">
<origin xyz="-1.1102230246251565404e-16 0.1210000000000017728 -5.5511151231257827021e-17" rpy="-3.141592653589793116 1.4029555309302166103e-23 -2.5275930356699616297" />
<parent link="activearm" />
<child link="lta-passivarm" />
<axis xyz="0 0 1"/>
<limit effort="1" velocity="20" />
<joint_properties friction="0.0"/>
</joint>

<joint name="motorV" type="revolute">
<origin xyz="-0.56567383653931846421 -0.33786915395602329371 -0.30208674309345501241" rpy="1.570796326794896558 1.0498176278019926144 -3.141592653589793116" />
<parent link="lta-body" />
<child link="activearm" />
<axis xyz="0 0 1"/>
<limit effort="1" velocity="20" lower="0" upper="2.0943951023931952626"/>
<joint_properties friction="0.0"/>
</joint>

<link name="activearm_2">
<visual>
<origin xyz="0 0.060499999999999998224 -0.015000000000000013323" rpy="1.570796326794896558 -0 -1.3877787807814456755e-17" />
<geometry>
<mesh filename="package://arm/meshes/activearm.stl"/>
</geometry>
<material name="activearm_material">
<color rgba="0.79215686274509800047 0.81960784313725487671 0.93333333333333334814 1.0"/>
</material>
</visual>
<collision>
<origin xyz="0 0.060499999999999998224 -0.015000000000000013323" rpy="1.570796326794896558 -0 -1.3877787807814456755e-17" />
<geometry>
<mesh filename="package://arm/meshes/activearm.stl"/>
</geometry>
</collision>
<inertial>
<origin xyz="0 0 0" rpy="0 0 0"/>
<mass value="4" />
  <inertia ixx="0.00417" ixy="0" ixz="0" iyy="0.03083" iyz="0" izz="0.03333" />
  </inertial>
</link>

<link name="lta-passivarm_2">
<visual>
<origin xyz="0 0.14999999999999996669 0.015000000000000013323" rpy="1.570796326794896558 -3.6734198463196484624e-40 -5.5511151231257827021e-17" />
<geometry>
<mesh filename="package://arm/meshes/lta-passivarm.stl"/>
</geometry>
<material name="lta-passivarm_material">
<color rgba="0.79215686274509800047 0.81960784313725487671 0.93333333333333334814 1.0"/>
</material>
</visual>
<collision>
<origin xyz="0 0.14999999999999996669 0.015000000000000013323" rpy="1.570796326794896558 -3.6734198463196484624e-40 -5.5511151231257827021e-17" />
<geometry>
<mesh filename="package://arm/meshes/lta-passivarm.stl"/>
</geometry>
</collision>
<inertial>
<origin xyz="0 0 0" rpy="0 0 0"/>
<mass value="4" />
  <inertia ixx="0.00417" ixy="0" ixz="0" iyy="0.03083" iyz="0" izz="0.03333" />
  </inertial>
</link>

<joint name="elbowH" type="revolute">
<origin xyz="2.720046410331633524e-15 0.12100000000000182832 -0.030000000000000082157" rpy="-5.1648064932760115286e-24 -1.4008023803742507427e-23 2.311678298551733679" />
<parent link="activearm_2" />
<child link="lta-passivarm_2" />
<axis xyz="0 0 1"/>
<limit effort="1" velocity="20" />
<joint_properties friction="0.0"/>
</joint>

<joint name="motorH" type="revolute">
<origin xyz="-0.40567438532566235665 -0.33786915395602329371 -0.30166768304039565107" rpy="-1.570796326794896558 -1.4701964741888278176 2.4104629166993733823e-23" />
<parent link="lta-body" />
<child link="activearm_2" />
<axis xyz="0 0 1"/>
<limit effort="1" velocity="20" lower="-2.0943951023931952626" upper="0"/>
<joint_properties friction="0.0"/>
</joint>


</robot>
